Watching for file changes with StatReloader
Not Found: /
"GET / HTTP/1.1" 404 2167
Not Found: /docs
"GET /docs HTTP/1.1" 404 2197
"GET /game/ HTTP/1.1" 200 12
"GET /game/kub HTTP/1.1" 200 1
"GET /game/kub HTTP/1.1" 200 1
"GET /game/kub HTTP/1.1" 200 1
"GET /game/kub HTTP/1.1" 200 1
"GET /game/kub HTTP/1.1" 200 1
"GET /game/kub HTTP/1.1" 200 1
C:\python_projects\FrameworkDjango\Seminar\myproject\gameapp\views.py changed, reloading.
Watching for file changes with StatReloader
Watching for file changes with StatReloader
"GET /game/kub HTTP/1.1" 200 20
C:\python_projects\FrameworkDjango\Seminar\myproject\gameapp\views.py changed, reloading.
Watching for file changes with StatReloader
"GET /game/kub HTTP/1.1" 200 22
Watching for file changes with StatReloader
C:\python_projects\FrameworkDjango\Seminar\myproject\gameapp\views.py changed, reloading.
Watching for file changes with StatReloader
Not Found: /
"GET / HTTP/1.1" 404 2167
Not Found: /favicon.ico
"GET /favicon.ico HTTP/1.1" 404 2218
Not Found: /orel_reshka
"GET /orel_reshka HTTP/1.1" 404 2218
Not Found: /game/coin
"GET /game/coin HTTP/1.1" 404 2798
"GET /game/orel_reshka HTTP/1.1" 200 8
"GET /game/orel_reshka HTTP/1.1" 200 8
"GET /game/orel_reshka HTTP/1.1" 200 8
"GET /game/orel_reshka HTTP/1.1" 200 8
"GET /game/orel_reshka HTTP/1.1" 200 10
"GET /game/orel_reshka HTTP/1.1" 200 8
C:\python_projects\FrameworkDjango\Seminar\myproject\gameapp\views.py changed, reloading.
Watching for file changes with StatReloader
C:\python_projects\FrameworkDjango\Seminar\myproject\gameapp\views.py changed, reloading.
Watching for file changes with StatReloader
Watching for file changes with StatReloader
"GET /game/orel_reshka HTTP/1.1" 200 8
"GET /game/orel_reshka HTTP/1.1" 200 10
"GET /game/orel_reshka HTTP/1.1" 200 8
"GET /game/orel_reshka HTTP/1.1" 200 8
Watching for file changes with StatReloader
Not Found: /
"GET / HTTP/1.1" 404 2167
Internal Server Error: /game/orel_reshka
Traceback (most recent call last):
  File "C:\python_projects\FrameworkDjango\venv\Lib\site-packages\django\db\backends\utils.py", line 105, in _execute
    return self.cursor.execute(sql, params)
           ^^^^^^^^^^^^^^^^^^^^^^^^^^^^^^^^
  File "C:\python_projects\FrameworkDjango\venv\Lib\site-packages\django\db\backends\sqlite3\base.py", line 329, in execute
    return super().execute(query, params)
           ^^^^^^^^^^^^^^^^^^^^^^^^^^^^^^
sqlite3.OperationalError: no such table: gameapp_coin

The above exception was the direct cause of the following exception:

Traceback (most recent call last):
  File "C:\python_projects\FrameworkDjango\venv\Lib\site-packages\django\core\handlers\exception.py", line 55, in inner
    response = get_response(request)
               ^^^^^^^^^^^^^^^^^^^^^
  File "C:\python_projects\FrameworkDjango\venv\Lib\site-packages\django\core\handlers\base.py", line 197, in _get_response
    response = wrapped_callback(request, *callback_args, **callback_kwargs)
               ^^^^^^^^^^^^^^^^^^^^^^^^^^^^^^^^^^^^^^^^^^^^^^^^^^^^^^^^^^^^
  File "C:\python_projects\FrameworkDjango\seminar\myproject\gameapp\views.py", line 16, in orel_reshka
    arg.save()
  File "C:\python_projects\FrameworkDjango\venv\Lib\site-packages\django\db\models\base.py", line 822, in save
    self.save_base(
  File "C:\python_projects\FrameworkDjango\venv\Lib\site-packages\django\db\models\base.py", line 909, in save_base
    updated = self._save_table(
              ^^^^^^^^^^^^^^^^^
  File "C:\python_projects\FrameworkDjango\venv\Lib\site-packages\django\db\models\base.py", line 1067, in _save_table
    results = self._do_insert(
              ^^^^^^^^^^^^^^^^
  File "C:\python_projects\FrameworkDjango\venv\Lib\site-packages\django\db\models\base.py", line 1108, in _do_insert
    return manager._insert(
           ^^^^^^^^^^^^^^^^
  File "C:\python_projects\FrameworkDjango\venv\Lib\site-packages\django\db\models\manager.py", line 87, in manager_method
    return getattr(self.get_queryset(), name)(*args, **kwargs)
           ^^^^^^^^^^^^^^^^^^^^^^^^^^^^^^^^^^^^^^^^^^^^^^^^^^^
  File "C:\python_projects\FrameworkDjango\venv\Lib\site-packages\django\db\models\query.py", line 1847, in _insert
    return query.get_compiler(using=using).execute_sql(returning_fields)
           ^^^^^^^^^^^^^^^^^^^^^^^^^^^^^^^^^^^^^^^^^^^^^^^^^^^^^^^^^^^^^
  File "C:\python_projects\FrameworkDjango\venv\Lib\site-packages\django\db\models\sql\compiler.py", line 1823, in execute_sql
    cursor.execute(sql, params)
  File "C:\python_projects\FrameworkDjango\venv\Lib\site-packages\django\db\backends\utils.py", line 122, in execute
    return super().execute(sql, params)
           ^^^^^^^^^^^^^^^^^^^^^^^^^^^^
  File "C:\python_projects\FrameworkDjango\venv\Lib\site-packages\django\db\backends\utils.py", line 79, in execute
    return self._execute_with_wrappers(
           ^^^^^^^^^^^^^^^^^^^^^^^^^^^^
  File "C:\python_projects\FrameworkDjango\venv\Lib\site-packages\django\db\backends\utils.py", line 92, in _execute_with_wrappers
    return executor(sql, params, many, context)
           ^^^^^^^^^^^^^^^^^^^^^^^^^^^^^^^^^^^^
  File "C:\python_projects\FrameworkDjango\venv\Lib\site-packages\django\db\backends\utils.py", line 100, in _execute
    with self.db.wrap_database_errors:
  File "C:\python_projects\FrameworkDjango\venv\Lib\site-packages\django\db\utils.py", line 91, in __exit__
    raise dj_exc_value.with_traceback(traceback) from exc_value
  File "C:\python_projects\FrameworkDjango\venv\Lib\site-packages\django\db\backends\utils.py", line 105, in _execute
    return self.cursor.execute(sql, params)
           ^^^^^^^^^^^^^^^^^^^^^^^^^^^^^^^^
  File "C:\python_projects\FrameworkDjango\venv\Lib\site-packages\django\db\backends\sqlite3\base.py", line 329, in execute
    return super().execute(query, params)
           ^^^^^^^^^^^^^^^^^^^^^^^^^^^^^^
django.db.utils.OperationalError: no such table: gameapp_coin
"GET /game/orel_reshka HTTP/1.1" 500 145159
Internal Server Error: /game/orel_reshka
Traceback (most recent call last):
  File "C:\python_projects\FrameworkDjango\venv\Lib\site-packages\django\db\backends\utils.py", line 105, in _execute
    return self.cursor.execute(sql, params)
           ^^^^^^^^^^^^^^^^^^^^^^^^^^^^^^^^
  File "C:\python_projects\FrameworkDjango\venv\Lib\site-packages\django\db\backends\sqlite3\base.py", line 329, in execute
    return super().execute(query, params)
           ^^^^^^^^^^^^^^^^^^^^^^^^^^^^^^
sqlite3.OperationalError: no such table: gameapp_coin

The above exception was the direct cause of the following exception:

Traceback (most recent call last):
  File "C:\python_projects\FrameworkDjango\venv\Lib\site-packages\django\core\handlers\exception.py", line 55, in inner
    response = get_response(request)
               ^^^^^^^^^^^^^^^^^^^^^
  File "C:\python_projects\FrameworkDjango\venv\Lib\site-packages\django\core\handlers\base.py", line 197, in _get_response
    response = wrapped_callback(request, *callback_args, **callback_kwargs)
               ^^^^^^^^^^^^^^^^^^^^^^^^^^^^^^^^^^^^^^^^^^^^^^^^^^^^^^^^^^^^
  File "C:\python_projects\FrameworkDjango\seminar\myproject\gameapp\views.py", line 16, in orel_reshka
    arg.save()
  File "C:\python_projects\FrameworkDjango\venv\Lib\site-packages\django\db\models\base.py", line 822, in save
    self.save_base(
  File "C:\python_projects\FrameworkDjango\venv\Lib\site-packages\django\db\models\base.py", line 909, in save_base
    updated = self._save_table(
              ^^^^^^^^^^^^^^^^^
  File "C:\python_projects\FrameworkDjango\venv\Lib\site-packages\django\db\models\base.py", line 1067, in _save_table
    results = self._do_insert(
              ^^^^^^^^^^^^^^^^
  File "C:\python_projects\FrameworkDjango\venv\Lib\site-packages\django\db\models\base.py", line 1108, in _do_insert
    return manager._insert(
           ^^^^^^^^^^^^^^^^
  File "C:\python_projects\FrameworkDjango\venv\Lib\site-packages\django\db\models\manager.py", line 87, in manager_method
    return getattr(self.get_queryset(), name)(*args, **kwargs)
           ^^^^^^^^^^^^^^^^^^^^^^^^^^^^^^^^^^^^^^^^^^^^^^^^^^^
  File "C:\python_projects\FrameworkDjango\venv\Lib\site-packages\django\db\models\query.py", line 1847, in _insert
    return query.get_compiler(using=using).execute_sql(returning_fields)
           ^^^^^^^^^^^^^^^^^^^^^^^^^^^^^^^^^^^^^^^^^^^^^^^^^^^^^^^^^^^^^
  File "C:\python_projects\FrameworkDjango\venv\Lib\site-packages\django\db\models\sql\compiler.py", line 1823, in execute_sql
    cursor.execute(sql, params)
  File "C:\python_projects\FrameworkDjango\venv\Lib\site-packages\django\db\backends\utils.py", line 122, in execute
    return super().execute(sql, params)
           ^^^^^^^^^^^^^^^^^^^^^^^^^^^^
  File "C:\python_projects\FrameworkDjango\venv\Lib\site-packages\django\db\backends\utils.py", line 79, in execute
    return self._execute_with_wrappers(
           ^^^^^^^^^^^^^^^^^^^^^^^^^^^^
  File "C:\python_projects\FrameworkDjango\venv\Lib\site-packages\django\db\backends\utils.py", line 92, in _execute_with_wrappers
    return executor(sql, params, many, context)
           ^^^^^^^^^^^^^^^^^^^^^^^^^^^^^^^^^^^^
  File "C:\python_projects\FrameworkDjango\venv\Lib\site-packages\django\db\backends\utils.py", line 100, in _execute
    with self.db.wrap_database_errors:
  File "C:\python_projects\FrameworkDjango\venv\Lib\site-packages\django\db\utils.py", line 91, in __exit__
    raise dj_exc_value.with_traceback(traceback) from exc_value
  File "C:\python_projects\FrameworkDjango\venv\Lib\site-packages\django\db\backends\utils.py", line 105, in _execute
    return self.cursor.execute(sql, params)
           ^^^^^^^^^^^^^^^^^^^^^^^^^^^^^^^^
  File "C:\python_projects\FrameworkDjango\venv\Lib\site-packages\django\db\backends\sqlite3\base.py", line 329, in execute
    return super().execute(query, params)
           ^^^^^^^^^^^^^^^^^^^^^^^^^^^^^^
django.db.utils.OperationalError: no such table: gameapp_coin
"GET /game/orel_reshka HTTP/1.1" 500 145179
"GET /game HTTP/1.1" 301 0
"GET /game/ HTTP/1.1" 200 12
Internal Server Error: /game/orel_reshka
Traceback (most recent call last):
  File "C:\python_projects\FrameworkDjango\venv\Lib\site-packages\django\db\backends\utils.py", line 105, in _execute
    return self.cursor.execute(sql, params)
           ^^^^^^^^^^^^^^^^^^^^^^^^^^^^^^^^
  File "C:\python_projects\FrameworkDjango\venv\Lib\site-packages\django\db\backends\sqlite3\base.py", line 329, in execute
    return super().execute(query, params)
           ^^^^^^^^^^^^^^^^^^^^^^^^^^^^^^
sqlite3.OperationalError: no such table: gameapp_coin

The above exception was the direct cause of the following exception:

Traceback (most recent call last):
  File "C:\python_projects\FrameworkDjango\venv\Lib\site-packages\django\core\handlers\exception.py", line 55, in inner
    response = get_response(request)
               ^^^^^^^^^^^^^^^^^^^^^
  File "C:\python_projects\FrameworkDjango\venv\Lib\site-packages\django\core\handlers\base.py", line 197, in _get_response
    response = wrapped_callback(request, *callback_args, **callback_kwargs)
               ^^^^^^^^^^^^^^^^^^^^^^^^^^^^^^^^^^^^^^^^^^^^^^^^^^^^^^^^^^^^
  File "C:\python_projects\FrameworkDjango\seminar\myproject\gameapp\views.py", line 16, in orel_reshka
    arg.save()
  File "C:\python_projects\FrameworkDjango\venv\Lib\site-packages\django\db\models\base.py", line 822, in save
    self.save_base(
  File "C:\python_projects\FrameworkDjango\venv\Lib\site-packages\django\db\models\base.py", line 909, in save_base
    updated = self._save_table(
              ^^^^^^^^^^^^^^^^^
  File "C:\python_projects\FrameworkDjango\venv\Lib\site-packages\django\db\models\base.py", line 1067, in _save_table
    results = self._do_insert(
              ^^^^^^^^^^^^^^^^
  File "C:\python_projects\FrameworkDjango\venv\Lib\site-packages\django\db\models\base.py", line 1108, in _do_insert
    return manager._insert(
           ^^^^^^^^^^^^^^^^
  File "C:\python_projects\FrameworkDjango\venv\Lib\site-packages\django\db\models\manager.py", line 87, in manager_method
    return getattr(self.get_queryset(), name)(*args, **kwargs)
           ^^^^^^^^^^^^^^^^^^^^^^^^^^^^^^^^^^^^^^^^^^^^^^^^^^^
  File "C:\python_projects\FrameworkDjango\venv\Lib\site-packages\django\db\models\query.py", line 1847, in _insert
    return query.get_compiler(using=using).execute_sql(returning_fields)
           ^^^^^^^^^^^^^^^^^^^^^^^^^^^^^^^^^^^^^^^^^^^^^^^^^^^^^^^^^^^^^
  File "C:\python_projects\FrameworkDjango\venv\Lib\site-packages\django\db\models\sql\compiler.py", line 1823, in execute_sql
    cursor.execute(sql, params)
  File "C:\python_projects\FrameworkDjango\venv\Lib\site-packages\django\db\backends\utils.py", line 122, in execute
    return super().execute(sql, params)
           ^^^^^^^^^^^^^^^^^^^^^^^^^^^^
  File "C:\python_projects\FrameworkDjango\venv\Lib\site-packages\django\db\backends\utils.py", line 79, in execute
    return self._execute_with_wrappers(
           ^^^^^^^^^^^^^^^^^^^^^^^^^^^^
  File "C:\python_projects\FrameworkDjango\venv\Lib\site-packages\django\db\backends\utils.py", line 92, in _execute_with_wrappers
    return executor(sql, params, many, context)
           ^^^^^^^^^^^^^^^^^^^^^^^^^^^^^^^^^^^^
  File "C:\python_projects\FrameworkDjango\venv\Lib\site-packages\django\db\backends\utils.py", line 100, in _execute
    with self.db.wrap_database_errors:
  File "C:\python_projects\FrameworkDjango\venv\Lib\site-packages\django\db\utils.py", line 91, in __exit__
    raise dj_exc_value.with_traceback(traceback) from exc_value
  File "C:\python_projects\FrameworkDjango\venv\Lib\site-packages\django\db\backends\utils.py", line 105, in _execute
    return self.cursor.execute(sql, params)
           ^^^^^^^^^^^^^^^^^^^^^^^^^^^^^^^^
  File "C:\python_projects\FrameworkDjango\venv\Lib\site-packages\django\db\backends\sqlite3\base.py", line 329, in execute
    return super().execute(query, params)
           ^^^^^^^^^^^^^^^^^^^^^^^^^^^^^^
django.db.utils.OperationalError: no such table: gameapp_coin
"GET /game/orel_reshka HTTP/1.1" 500 145022
Watching for file changes with StatReloader
Internal Server Error: /game/orel_reshka
Traceback (most recent call last):
  File "C:\python_projects\FrameworkDjango\venv\Lib\site-packages\django\db\backends\utils.py", line 105, in _execute
    return self.cursor.execute(sql, params)
           ^^^^^^^^^^^^^^^^^^^^^^^^^^^^^^^^
  File "C:\python_projects\FrameworkDjango\venv\Lib\site-packages\django\db\backends\sqlite3\base.py", line 329, in execute
    return super().execute(query, params)
           ^^^^^^^^^^^^^^^^^^^^^^^^^^^^^^
sqlite3.OperationalError: no such table: gameapp_coin

The above exception was the direct cause of the following exception:

Traceback (most recent call last):
  File "C:\python_projects\FrameworkDjango\venv\Lib\site-packages\django\core\handlers\exception.py", line 55, in inner
    response = get_response(request)
               ^^^^^^^^^^^^^^^^^^^^^
  File "C:\python_projects\FrameworkDjango\venv\Lib\site-packages\django\core\handlers\base.py", line 197, in _get_response
    response = wrapped_callback(request, *callback_args, **callback_kwargs)
               ^^^^^^^^^^^^^^^^^^^^^^^^^^^^^^^^^^^^^^^^^^^^^^^^^^^^^^^^^^^^
  File "C:\python_projects\FrameworkDjango\seminar\myproject\gameapp\views.py", line 16, in orel_reshka
    arg.save()
  File "C:\python_projects\FrameworkDjango\venv\Lib\site-packages\django\db\models\base.py", line 822, in save
    self.save_base(
  File "C:\python_projects\FrameworkDjango\venv\Lib\site-packages\django\db\models\base.py", line 909, in save_base
    updated = self._save_table(
              ^^^^^^^^^^^^^^^^^
  File "C:\python_projects\FrameworkDjango\venv\Lib\site-packages\django\db\models\base.py", line 1067, in _save_table
    results = self._do_insert(
              ^^^^^^^^^^^^^^^^
  File "C:\python_projects\FrameworkDjango\venv\Lib\site-packages\django\db\models\base.py", line 1108, in _do_insert
    return manager._insert(
           ^^^^^^^^^^^^^^^^
  File "C:\python_projects\FrameworkDjango\venv\Lib\site-packages\django\db\models\manager.py", line 87, in manager_method
    return getattr(self.get_queryset(), name)(*args, **kwargs)
           ^^^^^^^^^^^^^^^^^^^^^^^^^^^^^^^^^^^^^^^^^^^^^^^^^^^
  File "C:\python_projects\FrameworkDjango\venv\Lib\site-packages\django\db\models\query.py", line 1847, in _insert
    return query.get_compiler(using=using).execute_sql(returning_fields)
           ^^^^^^^^^^^^^^^^^^^^^^^^^^^^^^^^^^^^^^^^^^^^^^^^^^^^^^^^^^^^^
  File "C:\python_projects\FrameworkDjango\venv\Lib\site-packages\django\db\models\sql\compiler.py", line 1823, in execute_sql
    cursor.execute(sql, params)
  File "C:\python_projects\FrameworkDjango\venv\Lib\site-packages\django\db\backends\utils.py", line 122, in execute
    return super().execute(sql, params)
           ^^^^^^^^^^^^^^^^^^^^^^^^^^^^
  File "C:\python_projects\FrameworkDjango\venv\Lib\site-packages\django\db\backends\utils.py", line 79, in execute
    return self._execute_with_wrappers(
           ^^^^^^^^^^^^^^^^^^^^^^^^^^^^
  File "C:\python_projects\FrameworkDjango\venv\Lib\site-packages\django\db\backends\utils.py", line 92, in _execute_with_wrappers
    return executor(sql, params, many, context)
           ^^^^^^^^^^^^^^^^^^^^^^^^^^^^^^^^^^^^
  File "C:\python_projects\FrameworkDjango\venv\Lib\site-packages\django\db\backends\utils.py", line 100, in _execute
    with self.db.wrap_database_errors:
  File "C:\python_projects\FrameworkDjango\venv\Lib\site-packages\django\db\utils.py", line 91, in __exit__
    raise dj_exc_value.with_traceback(traceback) from exc_value
  File "C:\python_projects\FrameworkDjango\venv\Lib\site-packages\django\db\backends\utils.py", line 105, in _execute
    return self.cursor.execute(sql, params)
           ^^^^^^^^^^^^^^^^^^^^^^^^^^^^^^^^
  File "C:\python_projects\FrameworkDjango\venv\Lib\site-packages\django\db\backends\sqlite3\base.py", line 329, in execute
    return super().execute(query, params)
           ^^^^^^^^^^^^^^^^^^^^^^^^^^^^^^
django.db.utils.OperationalError: no such table: gameapp_coin
"GET /game/orel_reshka HTTP/1.1" 500 145159
"GET /game/ HTTP/1.1" 200 12
Internal Server Error: /game/orel_reshka
Traceback (most recent call last):
  File "C:\python_projects\FrameworkDjango\venv\Lib\site-packages\django\db\backends\utils.py", line 105, in _execute
    return self.cursor.execute(sql, params)
           ^^^^^^^^^^^^^^^^^^^^^^^^^^^^^^^^
  File "C:\python_projects\FrameworkDjango\venv\Lib\site-packages\django\db\backends\sqlite3\base.py", line 329, in execute
    return super().execute(query, params)
           ^^^^^^^^^^^^^^^^^^^^^^^^^^^^^^
sqlite3.OperationalError: no such table: gameapp_coin

The above exception was the direct cause of the following exception:

Traceback (most recent call last):
  File "C:\python_projects\FrameworkDjango\venv\Lib\site-packages\django\core\handlers\exception.py", line 55, in inner
    response = get_response(request)
               ^^^^^^^^^^^^^^^^^^^^^
  File "C:\python_projects\FrameworkDjango\venv\Lib\site-packages\django\core\handlers\base.py", line 197, in _get_response
    response = wrapped_callback(request, *callback_args, **callback_kwargs)
               ^^^^^^^^^^^^^^^^^^^^^^^^^^^^^^^^^^^^^^^^^^^^^^^^^^^^^^^^^^^^
  File "C:\python_projects\FrameworkDjango\seminar\myproject\gameapp\views.py", line 16, in orel_reshka
    arg.save()
  File "C:\python_projects\FrameworkDjango\venv\Lib\site-packages\django\db\models\base.py", line 822, in save
    self.save_base(
  File "C:\python_projects\FrameworkDjango\venv\Lib\site-packages\django\db\models\base.py", line 909, in save_base
    updated = self._save_table(
              ^^^^^^^^^^^^^^^^^
  File "C:\python_projects\FrameworkDjango\venv\Lib\site-packages\django\db\models\base.py", line 1067, in _save_table
    results = self._do_insert(
              ^^^^^^^^^^^^^^^^
  File "C:\python_projects\FrameworkDjango\venv\Lib\site-packages\django\db\models\base.py", line 1108, in _do_insert
    return manager._insert(
           ^^^^^^^^^^^^^^^^
  File "C:\python_projects\FrameworkDjango\venv\Lib\site-packages\django\db\models\manager.py", line 87, in manager_method
    return getattr(self.get_queryset(), name)(*args, **kwargs)
           ^^^^^^^^^^^^^^^^^^^^^^^^^^^^^^^^^^^^^^^^^^^^^^^^^^^
  File "C:\python_projects\FrameworkDjango\venv\Lib\site-packages\django\db\models\query.py", line 1847, in _insert
    return query.get_compiler(using=using).execute_sql(returning_fields)
           ^^^^^^^^^^^^^^^^^^^^^^^^^^^^^^^^^^^^^^^^^^^^^^^^^^^^^^^^^^^^^
  File "C:\python_projects\FrameworkDjango\venv\Lib\site-packages\django\db\models\sql\compiler.py", line 1823, in execute_sql
    cursor.execute(sql, params)
  File "C:\python_projects\FrameworkDjango\venv\Lib\site-packages\django\db\backends\utils.py", line 122, in execute
    return super().execute(sql, params)
           ^^^^^^^^^^^^^^^^^^^^^^^^^^^^
  File "C:\python_projects\FrameworkDjango\venv\Lib\site-packages\django\db\backends\utils.py", line 79, in execute
    return self._execute_with_wrappers(
           ^^^^^^^^^^^^^^^^^^^^^^^^^^^^
  File "C:\python_projects\FrameworkDjango\venv\Lib\site-packages\django\db\backends\utils.py", line 92, in _execute_with_wrappers
    return executor(sql, params, many, context)
           ^^^^^^^^^^^^^^^^^^^^^^^^^^^^^^^^^^^^
  File "C:\python_projects\FrameworkDjango\venv\Lib\site-packages\django\db\backends\utils.py", line 100, in _execute
    with self.db.wrap_database_errors:
  File "C:\python_projects\FrameworkDjango\venv\Lib\site-packages\django\db\utils.py", line 91, in __exit__
    raise dj_exc_value.with_traceback(traceback) from exc_value
  File "C:\python_projects\FrameworkDjango\venv\Lib\site-packages\django\db\backends\utils.py", line 105, in _execute
    return self.cursor.execute(sql, params)
           ^^^^^^^^^^^^^^^^^^^^^^^^^^^^^^^^
  File "C:\python_projects\FrameworkDjango\venv\Lib\site-packages\django\db\backends\sqlite3\base.py", line 329, in execute
    return super().execute(query, params)
           ^^^^^^^^^^^^^^^^^^^^^^^^^^^^^^
django.db.utils.OperationalError: no such table: gameapp_coin
"GET /game/orel_reshka HTTP/1.1" 500 145042
C:\python_projects\FrameworkDjango\Seminar\myproject\gameapp\views.py changed, reloading.
Watching for file changes with StatReloader
"GET /game/orel_reshka HTTP/1.1" 200 8
C:\python_projects\FrameworkDjango\Seminar\myproject\gameapp\views.py changed, reloading.
Watching for file changes with StatReloader
Internal Server Error: /game/orel_reshka
Traceback (most recent call last):
  File "C:\python_projects\FrameworkDjango\venv\Lib\site-packages\django\db\backends\utils.py", line 105, in _execute
    return self.cursor.execute(sql, params)
           ^^^^^^^^^^^^^^^^^^^^^^^^^^^^^^^^
  File "C:\python_projects\FrameworkDjango\venv\Lib\site-packages\django\db\backends\sqlite3\base.py", line 329, in execute
    return super().execute(query, params)
           ^^^^^^^^^^^^^^^^^^^^^^^^^^^^^^
sqlite3.OperationalError: no such table: gameapp_coin

The above exception was the direct cause of the following exception:

Traceback (most recent call last):
  File "C:\python_projects\FrameworkDjango\venv\Lib\site-packages\django\core\handlers\exception.py", line 55, in inner
    response = get_response(request)
               ^^^^^^^^^^^^^^^^^^^^^
  File "C:\python_projects\FrameworkDjango\venv\Lib\site-packages\django\core\handlers\base.py", line 197, in _get_response
    response = wrapped_callback(request, *callback_args, **callback_kwargs)
               ^^^^^^^^^^^^^^^^^^^^^^^^^^^^^^^^^^^^^^^^^^^^^^^^^^^^^^^^^^^^
  File "C:\python_projects\FrameworkDjango\seminar\myproject\gameapp\views.py", line 16, in orel_reshka
    arg.save()
  File "C:\python_projects\FrameworkDjango\venv\Lib\site-packages\django\db\models\base.py", line 822, in save
    self.save_base(
  File "C:\python_projects\FrameworkDjango\venv\Lib\site-packages\django\db\models\base.py", line 909, in save_base
    updated = self._save_table(
              ^^^^^^^^^^^^^^^^^
  File "C:\python_projects\FrameworkDjango\venv\Lib\site-packages\django\db\models\base.py", line 1067, in _save_table
    results = self._do_insert(
              ^^^^^^^^^^^^^^^^
  File "C:\python_projects\FrameworkDjango\venv\Lib\site-packages\django\db\models\base.py", line 1108, in _do_insert
    return manager._insert(
           ^^^^^^^^^^^^^^^^
  File "C:\python_projects\FrameworkDjango\venv\Lib\site-packages\django\db\models\manager.py", line 87, in manager_method
    return getattr(self.get_queryset(), name)(*args, **kwargs)
           ^^^^^^^^^^^^^^^^^^^^^^^^^^^^^^^^^^^^^^^^^^^^^^^^^^^
  File "C:\python_projects\FrameworkDjango\venv\Lib\site-packages\django\db\models\query.py", line 1847, in _insert
    return query.get_compiler(using=using).execute_sql(returning_fields)
           ^^^^^^^^^^^^^^^^^^^^^^^^^^^^^^^^^^^^^^^^^^^^^^^^^^^^^^^^^^^^^
  File "C:\python_projects\FrameworkDjango\venv\Lib\site-packages\django\db\models\sql\compiler.py", line 1823, in execute_sql
    cursor.execute(sql, params)
  File "C:\python_projects\FrameworkDjango\venv\Lib\site-packages\django\db\backends\utils.py", line 122, in execute
    return super().execute(sql, params)
           ^^^^^^^^^^^^^^^^^^^^^^^^^^^^
  File "C:\python_projects\FrameworkDjango\venv\Lib\site-packages\django\db\backends\utils.py", line 79, in execute
    return self._execute_with_wrappers(
           ^^^^^^^^^^^^^^^^^^^^^^^^^^^^
  File "C:\python_projects\FrameworkDjango\venv\Lib\site-packages\django\db\backends\utils.py", line 92, in _execute_with_wrappers
    return executor(sql, params, many, context)
           ^^^^^^^^^^^^^^^^^^^^^^^^^^^^^^^^^^^^
  File "C:\python_projects\FrameworkDjango\venv\Lib\site-packages\django\db\backends\utils.py", line 100, in _execute
    with self.db.wrap_database_errors:
  File "C:\python_projects\FrameworkDjango\venv\Lib\site-packages\django\db\utils.py", line 91, in __exit__
    raise dj_exc_value.with_traceback(traceback) from exc_value
  File "C:\python_projects\FrameworkDjango\venv\Lib\site-packages\django\db\backends\utils.py", line 105, in _execute
    return self.cursor.execute(sql, params)
           ^^^^^^^^^^^^^^^^^^^^^^^^^^^^^^^^
  File "C:\python_projects\FrameworkDjango\venv\Lib\site-packages\django\db\backends\sqlite3\base.py", line 329, in execute
    return super().execute(query, params)
           ^^^^^^^^^^^^^^^^^^^^^^^^^^^^^^
django.db.utils.OperationalError: no such table: gameapp_coin
"GET /game/orel_reshka HTTP/1.1" 500 145159
Internal Server Error: /game/orel_reshka
Traceback (most recent call last):
  File "C:\python_projects\FrameworkDjango\venv\Lib\site-packages\django\db\backends\utils.py", line 105, in _execute
    return self.cursor.execute(sql, params)
           ^^^^^^^^^^^^^^^^^^^^^^^^^^^^^^^^
  File "C:\python_projects\FrameworkDjango\venv\Lib\site-packages\django\db\backends\sqlite3\base.py", line 329, in execute
    return super().execute(query, params)
           ^^^^^^^^^^^^^^^^^^^^^^^^^^^^^^
sqlite3.OperationalError: no such table: gameapp_coin

The above exception was the direct cause of the following exception:

Traceback (most recent call last):
  File "C:\python_projects\FrameworkDjango\venv\Lib\site-packages\django\core\handlers\exception.py", line 55, in inner
    response = get_response(request)
               ^^^^^^^^^^^^^^^^^^^^^
  File "C:\python_projects\FrameworkDjango\venv\Lib\site-packages\django\core\handlers\base.py", line 197, in _get_response
    response = wrapped_callback(request, *callback_args, **callback_kwargs)
               ^^^^^^^^^^^^^^^^^^^^^^^^^^^^^^^^^^^^^^^^^^^^^^^^^^^^^^^^^^^^
  File "C:\python_projects\FrameworkDjango\seminar\myproject\gameapp\views.py", line 16, in orel_reshka
    arg.save()
  File "C:\python_projects\FrameworkDjango\venv\Lib\site-packages\django\db\models\base.py", line 822, in save
    self.save_base(
  File "C:\python_projects\FrameworkDjango\venv\Lib\site-packages\django\db\models\base.py", line 909, in save_base
    updated = self._save_table(
              ^^^^^^^^^^^^^^^^^
  File "C:\python_projects\FrameworkDjango\venv\Lib\site-packages\django\db\models\base.py", line 1067, in _save_table
    results = self._do_insert(
              ^^^^^^^^^^^^^^^^
  File "C:\python_projects\FrameworkDjango\venv\Lib\site-packages\django\db\models\base.py", line 1108, in _do_insert
    return manager._insert(
           ^^^^^^^^^^^^^^^^
  File "C:\python_projects\FrameworkDjango\venv\Lib\site-packages\django\db\models\manager.py", line 87, in manager_method
    return getattr(self.get_queryset(), name)(*args, **kwargs)
           ^^^^^^^^^^^^^^^^^^^^^^^^^^^^^^^^^^^^^^^^^^^^^^^^^^^
  File "C:\python_projects\FrameworkDjango\venv\Lib\site-packages\django\db\models\query.py", line 1847, in _insert
    return query.get_compiler(using=using).execute_sql(returning_fields)
           ^^^^^^^^^^^^^^^^^^^^^^^^^^^^^^^^^^^^^^^^^^^^^^^^^^^^^^^^^^^^^
  File "C:\python_projects\FrameworkDjango\venv\Lib\site-packages\django\db\models\sql\compiler.py", line 1823, in execute_sql
    cursor.execute(sql, params)
  File "C:\python_projects\FrameworkDjango\venv\Lib\site-packages\django\db\backends\utils.py", line 122, in execute
    return super().execute(sql, params)
           ^^^^^^^^^^^^^^^^^^^^^^^^^^^^
  File "C:\python_projects\FrameworkDjango\venv\Lib\site-packages\django\db\backends\utils.py", line 79, in execute
    return self._execute_with_wrappers(
           ^^^^^^^^^^^^^^^^^^^^^^^^^^^^
  File "C:\python_projects\FrameworkDjango\venv\Lib\site-packages\django\db\backends\utils.py", line 92, in _execute_with_wrappers
    return executor(sql, params, many, context)
           ^^^^^^^^^^^^^^^^^^^^^^^^^^^^^^^^^^^^
  File "C:\python_projects\FrameworkDjango\venv\Lib\site-packages\django\db\backends\utils.py", line 100, in _execute
    with self.db.wrap_database_errors:
  File "C:\python_projects\FrameworkDjango\venv\Lib\site-packages\django\db\utils.py", line 91, in __exit__
    raise dj_exc_value.with_traceback(traceback) from exc_value
  File "C:\python_projects\FrameworkDjango\venv\Lib\site-packages\django\db\backends\utils.py", line 105, in _execute
    return self.cursor.execute(sql, params)
           ^^^^^^^^^^^^^^^^^^^^^^^^^^^^^^^^
  File "C:\python_projects\FrameworkDjango\venv\Lib\site-packages\django\db\backends\sqlite3\base.py", line 329, in execute
    return super().execute(query, params)
           ^^^^^^^^^^^^^^^^^^^^^^^^^^^^^^
django.db.utils.OperationalError: no such table: gameapp_coin
"GET /game/orel_reshka HTTP/1.1" 500 145179
C:\python_projects\FrameworkDjango\Seminar\myproject\gameapp\views.py changed, reloading.
Watching for file changes with StatReloader
Internal Server Error: /game/orel_reshka
Traceback (most recent call last):
  File "C:\python_projects\FrameworkDjango\venv\Lib\site-packages\django\db\backends\utils.py", line 105, in _execute
    return self.cursor.execute(sql, params)
           ^^^^^^^^^^^^^^^^^^^^^^^^^^^^^^^^
  File "C:\python_projects\FrameworkDjango\venv\Lib\site-packages\django\db\backends\sqlite3\base.py", line 329, in execute
    return super().execute(query, params)
           ^^^^^^^^^^^^^^^^^^^^^^^^^^^^^^
sqlite3.OperationalError: no such table: gameapp_coin

The above exception was the direct cause of the following exception:

Traceback (most recent call last):
  File "C:\python_projects\FrameworkDjango\venv\Lib\site-packages\django\core\handlers\exception.py", line 55, in inner
    response = get_response(request)
               ^^^^^^^^^^^^^^^^^^^^^
  File "C:\python_projects\FrameworkDjango\venv\Lib\site-packages\django\core\handlers\base.py", line 197, in _get_response
    response = wrapped_callback(request, *callback_args, **callback_kwargs)
               ^^^^^^^^^^^^^^^^^^^^^^^^^^^^^^^^^^^^^^^^^^^^^^^^^^^^^^^^^^^^
  File "C:\python_projects\FrameworkDjango\seminar\myproject\gameapp\views.py", line 16, in orel_reshka
    res_orel_reshka.save()
  File "C:\python_projects\FrameworkDjango\venv\Lib\site-packages\django\db\models\base.py", line 822, in save
    self.save_base(
  File "C:\python_projects\FrameworkDjango\venv\Lib\site-packages\django\db\models\base.py", line 909, in save_base
    updated = self._save_table(
              ^^^^^^^^^^^^^^^^^
  File "C:\python_projects\FrameworkDjango\venv\Lib\site-packages\django\db\models\base.py", line 1067, in _save_table
    results = self._do_insert(
              ^^^^^^^^^^^^^^^^
  File "C:\python_projects\FrameworkDjango\venv\Lib\site-packages\django\db\models\base.py", line 1108, in _do_insert
    return manager._insert(
           ^^^^^^^^^^^^^^^^
  File "C:\python_projects\FrameworkDjango\venv\Lib\site-packages\django\db\models\manager.py", line 87, in manager_method
    return getattr(self.get_queryset(), name)(*args, **kwargs)
           ^^^^^^^^^^^^^^^^^^^^^^^^^^^^^^^^^^^^^^^^^^^^^^^^^^^
  File "C:\python_projects\FrameworkDjango\venv\Lib\site-packages\django\db\models\query.py", line 1847, in _insert
    return query.get_compiler(using=using).execute_sql(returning_fields)
           ^^^^^^^^^^^^^^^^^^^^^^^^^^^^^^^^^^^^^^^^^^^^^^^^^^^^^^^^^^^^^
  File "C:\python_projects\FrameworkDjango\venv\Lib\site-packages\django\db\models\sql\compiler.py", line 1823, in execute_sql
    cursor.execute(sql, params)
  File "C:\python_projects\FrameworkDjango\venv\Lib\site-packages\django\db\backends\utils.py", line 122, in execute
    return super().execute(sql, params)
           ^^^^^^^^^^^^^^^^^^^^^^^^^^^^
  File "C:\python_projects\FrameworkDjango\venv\Lib\site-packages\django\db\backends\utils.py", line 79, in execute
    return self._execute_with_wrappers(
           ^^^^^^^^^^^^^^^^^^^^^^^^^^^^
  File "C:\python_projects\FrameworkDjango\venv\Lib\site-packages\django\db\backends\utils.py", line 92, in _execute_with_wrappers
    return executor(sql, params, many, context)
           ^^^^^^^^^^^^^^^^^^^^^^^^^^^^^^^^^^^^
  File "C:\python_projects\FrameworkDjango\venv\Lib\site-packages\django\db\backends\utils.py", line 100, in _execute
    with self.db.wrap_database_errors:
  File "C:\python_projects\FrameworkDjango\venv\Lib\site-packages\django\db\utils.py", line 91, in __exit__
    raise dj_exc_value.with_traceback(traceback) from exc_value
  File "C:\python_projects\FrameworkDjango\venv\Lib\site-packages\django\db\backends\utils.py", line 105, in _execute
    return self.cursor.execute(sql, params)
           ^^^^^^^^^^^^^^^^^^^^^^^^^^^^^^^^
  File "C:\python_projects\FrameworkDjango\venv\Lib\site-packages\django\db\backends\sqlite3\base.py", line 329, in execute
    return super().execute(query, params)
           ^^^^^^^^^^^^^^^^^^^^^^^^^^^^^^
django.db.utils.OperationalError: no such table: gameapp_coin
"GET /game/orel_reshka HTTP/1.1" 500 145231
C:\python_projects\FrameworkDjango\Seminar\myproject\gameapp\views.py changed, reloading.
Watching for file changes with StatReloader
"GET /game/orel_reshka HTTP/1.1" 200 10
"GET /game/orel_reshka HTTP/1.1" 200 8
"GET /game/orel_reshka HTTP/1.1" 200 8
"GET /game/orel_reshka HTTP/1.1" 200 8
C:\python_projects\FrameworkDjango\Seminar\myproject\gameapp\views.py changed, reloading.
Watching for file changes with StatReloader
Internal Server Error: /game/orel_reshka
Traceback (most recent call last):
  File "C:\python_projects\FrameworkDjango\venv\Lib\site-packages\django\db\backends\utils.py", line 105, in _execute
    return self.cursor.execute(sql, params)
           ^^^^^^^^^^^^^^^^^^^^^^^^^^^^^^^^
  File "C:\python_projects\FrameworkDjango\venv\Lib\site-packages\django\db\backends\sqlite3\base.py", line 329, in execute
    return super().execute(query, params)
           ^^^^^^^^^^^^^^^^^^^^^^^^^^^^^^
sqlite3.OperationalError: no such table: gameapp_coin

The above exception was the direct cause of the following exception:

Traceback (most recent call last):
  File "C:\python_projects\FrameworkDjango\venv\Lib\site-packages\django\core\handlers\exception.py", line 55, in inner
    response = get_response(request)
               ^^^^^^^^^^^^^^^^^^^^^
  File "C:\python_projects\FrameworkDjango\venv\Lib\site-packages\django\core\handlers\base.py", line 197, in _get_response
    response = wrapped_callback(request, *callback_args, **callback_kwargs)
               ^^^^^^^^^^^^^^^^^^^^^^^^^^^^^^^^^^^^^^^^^^^^^^^^^^^^^^^^^^^^
  File "C:\python_projects\FrameworkDjango\seminar\myproject\gameapp\views.py", line 16, in orel_reshka
    res_orel_reshka.save()
  File "C:\python_projects\FrameworkDjango\venv\Lib\site-packages\django\db\models\base.py", line 822, in save
    self.save_base(
  File "C:\python_projects\FrameworkDjango\venv\Lib\site-packages\django\db\models\base.py", line 909, in save_base
    updated = self._save_table(
              ^^^^^^^^^^^^^^^^^
  File "C:\python_projects\FrameworkDjango\venv\Lib\site-packages\django\db\models\base.py", line 1067, in _save_table
    results = self._do_insert(
              ^^^^^^^^^^^^^^^^
  File "C:\python_projects\FrameworkDjango\venv\Lib\site-packages\django\db\models\base.py", line 1108, in _do_insert
    return manager._insert(
           ^^^^^^^^^^^^^^^^
  File "C:\python_projects\FrameworkDjango\venv\Lib\site-packages\django\db\models\manager.py", line 87, in manager_method
    return getattr(self.get_queryset(), name)(*args, **kwargs)
           ^^^^^^^^^^^^^^^^^^^^^^^^^^^^^^^^^^^^^^^^^^^^^^^^^^^
  File "C:\python_projects\FrameworkDjango\venv\Lib\site-packages\django\db\models\query.py", line 1847, in _insert
    return query.get_compiler(using=using).execute_sql(returning_fields)
           ^^^^^^^^^^^^^^^^^^^^^^^^^^^^^^^^^^^^^^^^^^^^^^^^^^^^^^^^^^^^^
  File "C:\python_projects\FrameworkDjango\venv\Lib\site-packages\django\db\models\sql\compiler.py", line 1823, in execute_sql
    cursor.execute(sql, params)
  File "C:\python_projects\FrameworkDjango\venv\Lib\site-packages\django\db\backends\utils.py", line 122, in execute
    return super().execute(sql, params)
           ^^^^^^^^^^^^^^^^^^^^^^^^^^^^
  File "C:\python_projects\FrameworkDjango\venv\Lib\site-packages\django\db\backends\utils.py", line 79, in execute
    return self._execute_with_wrappers(
           ^^^^^^^^^^^^^^^^^^^^^^^^^^^^
  File "C:\python_projects\FrameworkDjango\venv\Lib\site-packages\django\db\backends\utils.py", line 92, in _execute_with_wrappers
    return executor(sql, params, many, context)
           ^^^^^^^^^^^^^^^^^^^^^^^^^^^^^^^^^^^^
  File "C:\python_projects\FrameworkDjango\venv\Lib\site-packages\django\db\backends\utils.py", line 100, in _execute
    with self.db.wrap_database_errors:
  File "C:\python_projects\FrameworkDjango\venv\Lib\site-packages\django\db\utils.py", line 91, in __exit__
    raise dj_exc_value.with_traceback(traceback) from exc_value
  File "C:\python_projects\FrameworkDjango\venv\Lib\site-packages\django\db\backends\utils.py", line 105, in _execute
    return self.cursor.execute(sql, params)
           ^^^^^^^^^^^^^^^^^^^^^^^^^^^^^^^^
  File "C:\python_projects\FrameworkDjango\venv\Lib\site-packages\django\db\backends\sqlite3\base.py", line 329, in execute
    return super().execute(query, params)
           ^^^^^^^^^^^^^^^^^^^^^^^^^^^^^^
django.db.utils.OperationalError: no such table: gameapp_coin
"GET /game/orel_reshka HTTP/1.1" 500 145236
Watching for file changes with StatReloader
"GET /game/orel_reshka HTTP/1.1" 200 10
"GET /game/orel_reshka HTTP/1.1" 200 8
"GET /game/orel_reshka HTTP/1.1" 200 8
"GET /game/orel_reshka HTTP/1.1" 200 8
"GET /game/orel_reshka HTTP/1.1" 200 8
"GET /game/orel_reshka HTTP/1.1" 200 8
Watching for file changes with StatReloader
"GET /game/orel_reshka HTTP/1.1" 200 10
"GET /game/coin_values HTTP/1.1" 200 12
C:\python_projects\FrameworkDjango\Seminar\myproject\gameapp\models.py changed, reloading.
Watching for file changes with StatReloader
C:\python_projects\FrameworkDjango\Seminar\myproject\gameapp\views.py changed, reloading.
Watching for file changes with StatReloader
"GET /game/coin_values HTTP/1.1" 200 22
"GET /game/coin_values HTTP/1.1" 200 22
C:\python_projects\FrameworkDjango\Seminar\myproject\gameapp\views.py changed, reloading.
Watching for file changes with StatReloader
Watching for file changes with StatReloader
Not Found: /favicon.ico
"GET /favicon.ico HTTP/1.1" 404 2323
Not Found: /blog/autors
"GET /blog/autors HTTP/1.1" 404 2560
Internal Server Error: /blog/autor
Traceback (most recent call last):
  File "C:\python_projects\FrameworkDjango\venv\Lib\site-packages\django\core\handlers\exception.py", line 55, in inner
    response = get_response(request)
               ^^^^^^^^^^^^^^^^^^^^^
  File "C:\python_projects\FrameworkDjango\venv\Lib\site-packages\django\core\handlers\base.py", line 197, in _get_response
    response = wrapped_callback(request, *callback_args, **callback_kwargs)
               ^^^^^^^^^^^^^^^^^^^^^^^^^^^^^^^^^^^^^^^^^^^^^^^^^^^^^^^^^^^^
  File "C:\python_projects\FrameworkDjango\seminar\myproject\blogapp\views.py", line 12, in view_autor
    autor = Autor(name=f'aaaa{i}', secondname=f'bbbb{i}', email=f'aaaa{i}@mail.ru',
            ^^^^^^^^^^^^^^^^^^^^^^^^^^^^^^^^^^^^^^^^^^^^^^^^^^^^^^^^^^^^^^^^^^^^^^^
  File "C:\python_projects\FrameworkDjango\venv\Lib\site-packages\django\db\models\base.py", line 567, in __init__
    raise TypeError(
TypeError: Autor() got unexpected keyword arguments: 'io'
"GET /blog/autor HTTP/1.1" 500 71935
Not Found: /blog/autors
"GET /blog/autors HTTP/1.1" 404 2560
Not Found: /blog/view_auto
"GET /blog/view_auto HTTP/1.1" 404 2569
Not Found: /blog/view_autor
"GET /blog/view_autor HTTP/1.1" 404 2572
"GET /blog/ HTTP/1.1" 200 12
C:\python_projects\FrameworkDjango\Seminar\myproject\blogapp\models.py changed, reloading.
Watching for file changes with StatReloader
"GET /blog/ HTTP/1.1" 200 12
Not Found: /blog/autor/
"GET /blog/autor/ HTTP/1.1" 404 2560
C:\python_projects\FrameworkDjango\Seminar\myproject\blogapp\urls.py changed, reloading.
Watching for file changes with StatReloader
Not Found: /blog/autor/
"GET /blog/autor/ HTTP/1.1" 404 2555
Not Found: /blog/autor/
"GET /blog/autor/ HTTP/1.1" 404 2555
C:\python_projects\FrameworkDjango\Seminar\myproject\blogapp\urls.py changed, reloading.
Watching for file changes with StatReloader
C:\python_projects\FrameworkDjango\Seminar\myproject\blogapp\views.py changed, reloading.
Watching for file changes with StatReloader
Not Found: /blog/autor/
"GET /blog/autor/ HTTP/1.1" 404 2560
Not Found: /blog/autor/
"GET /blog/autor/ HTTP/1.1" 404 2560
Not Found: /blog/autor/
"GET /blog/autor/ HTTP/1.1" 404 2560
"GET /blog HTTP/1.1" 301 0
"GET /blog/ HTTP/1.1" 200 12
Internal Server Error: /blog/autor
Traceback (most recent call last):
  File "C:\python_projects\FrameworkDjango\venv\Lib\site-packages\django\core\handlers\exception.py", line 55, in inner
    response = get_response(request)
               ^^^^^^^^^^^^^^^^^^^^^
  File "C:\python_projects\FrameworkDjango\venv\Lib\site-packages\django\core\handlers\base.py", line 197, in _get_response
    response = wrapped_callback(request, *callback_args, **callback_kwargs)
               ^^^^^^^^^^^^^^^^^^^^^^^^^^^^^^^^^^^^^^^^^^^^^^^^^^^^^^^^^^^^
  File "C:\python_projects\FrameworkDjango\seminar\myproject\blogapp\views.py", line 12, in view_autor
    autor = Autor(
            ^^^^^^
  File "C:\python_projects\FrameworkDjango\venv\Lib\site-packages\django\db\models\base.py", line 567, in __init__
    raise TypeError(
TypeError: Autor() got unexpected keyword arguments: 'io'
"GET /blog/autor HTTP/1.1" 500 71973
Not Found: /blog/view_autor
"GET /blog/view_autor HTTP/1.1" 404 2572
Watching for file changes with StatReloader
"GET /blog/ HTTP/1.1" 200 12
Internal Server Error: /blog/autor
Traceback (most recent call last):
  File "C:\python_projects\FrameworkDjango\venv\Lib\site-packages\django\core\handlers\exception.py", line 55, in inner
    response = get_response(request)
               ^^^^^^^^^^^^^^^^^^^^^
  File "C:\python_projects\FrameworkDjango\venv\Lib\site-packages\django\core\handlers\base.py", line 197, in _get_response
    response = wrapped_callback(request, *callback_args, **callback_kwargs)
               ^^^^^^^^^^^^^^^^^^^^^^^^^^^^^^^^^^^^^^^^^^^^^^^^^^^^^^^^^^^^
  File "C:\python_projects\FrameworkDjango\seminar\myproject\blogapp\views.py", line 12, in view_autor
    autor = Autor(
            ^^^^^^
  File "C:\python_projects\FrameworkDjango\venv\Lib\site-packages\django\db\models\base.py", line 567, in __init__
    raise TypeError(
TypeError: Autor() got unexpected keyword arguments: 'io'
"GET /blog/autor HTTP/1.1" 500 71972
Not Found: /blog/autors
"GET /blog/autors HTTP/1.1" 404 2560
Not Found: /blog/view_autor
"GET /blog/view_autor HTTP/1.1" 404 2572
C:\python_projects\FrameworkDjango\Seminar\myproject\blogapp\views.py changed, reloading.
Watching for file changes with StatReloader
- Broken pipe from ('127.0.0.1', 64327)
"GET /blog/autor HTTP/1.1" 200 5
Watching for file changes with StatReloader
"GET /blog/ HTTP/1.1" 200 12
